============================= test session starts =============================
platform win32 -- Python 3.11.0, pytest-7.4.0, pluggy-1.5.0 -- C:\Users\SEDUC\Desktop\PROJETOS\omni_gerador_artigos\venv\Scripts\python.exe
cachedir: .pytest_cache
rootdir: D:\PROJETOS\SISTEMAS
configfile: pytest.ini
plugins: anyio-4.9.0, asyncio-0.21.1, cov-4.1.0, mock-3.11.1
asyncio: mode=Mode.STRICT
collecting ... collected 307 items

tests\integration\test_api_blogs_prompts.py::test_crud_blog PASSED       [  0%]
tests\integration\test_api_blogs_prompts.py::test_crud_prompts PASSED    [  0%]
tests\integration\test_api_template_generate.py::test_index_template FAILED [  0%]
tests\integration\test_api_template_generate.py::test_generate_sem_dados FAILED [  1%]
tests\integration\test_autenticacao_permissao.py::test_endpoint_protegido_token_valido FAILED [  1%]

================================== FAILURES ===================================
_____________________________ test_index_template _____________________________

    def test_index_template():
        with create_app().test_client() as c:
            resp = c.get('/')
>           assert resp.status_code == 200
E           assert 404 == 200
E            +  where 404 = <WrapperTestResponse streamed [404 NOT FOUND]>.status_code

tests\integration\test_api_template_generate.py:7: AssertionError
___________________________ test_generate_sem_dados ___________________________

    def test_generate_sem_dados():
        with create_app().test_client() as c:
            resp = c.post('/generate', data={})
>           assert resp.status_code == 200
E           assert 500 == 200
E            +  where 500 = <WrapperTestResponse streamed [500 INTERNAL SERVER ERROR]>.status_code

tests\integration\test_api_template_generate.py:13: AssertionError
------------------------------ Captured log call ------------------------------
ERROR    app.app_factory:app.py:875 Exception on /generate [POST]
Traceback (most recent call last):
  File "D:\PROJETOS\SISTEMAS\omni_writer\app\routes.py", line 105, in generate
    return render_template('index.html', modelos=MODELOS_SUPORTADOS, error='Dados inv├ílidos'), 400
           ^^^^^^^^^^^^^^^^^^^^^^^^^^^^^^^^^^^^^^^^^^^^^^^^^^^^^^^^^^^^^^^^^^^^^^^^^^^^^^^^^^
  File "C:\Users\SEDUC\Desktop\PROJETOS\omni_gerador_artigos\venv\Lib\site-packages\flask\templating.py", line 149, in render_template
    template = app.jinja_env.get_or_select_template(template_name_or_list)
               ^^^^^^^^^^^^^^^^^^^^^^^^^^^^^^^^^^^^^^^^^^^^^^^^^^^^^^^^^^^
  File "C:\Users\SEDUC\Desktop\PROJETOS\omni_gerador_artigos\venv\Lib\site-packages\jinja2\environment.py", line 1087, in get_or_select_template
    return self.get_template(template_name_or_list, parent, globals)
           ^^^^^^^^^^^^^^^^^^^^^^^^^^^^^^^^^^^^^^^^^^^^^^^^^^^^^^^^^
  File "C:\Users\SEDUC\Desktop\PROJETOS\omni_gerador_artigos\venv\Lib\site-packages\jinja2\environment.py", line 1016, in get_template
    return self._load_template(name, globals)
           ^^^^^^^^^^^^^^^^^^^^^^^^^^^^^^^^^^
  File "C:\Users\SEDUC\Desktop\PROJETOS\omni_gerador_artigos\venv\Lib\site-packages\jinja2\environment.py", line 975, in _load_template
    template = self.loader.load(self, name, self.make_globals(globals))
               ^^^^^^^^^^^^^^^^^^^^^^^^^^^^^^^^^^^^^^^^^^^^^^^^^^^^^^^^
  File "C:\Users\SEDUC\Desktop\PROJETOS\omni_gerador_artigos\venv\Lib\site-packages\jinja2\loaders.py", line 126, in load
    source, filename, uptodate = self.get_source(environment, name)
                                 ^^^^^^^^^^^^^^^^^^^^^^^^^^^^^^^^^^
  File "C:\Users\SEDUC\Desktop\PROJETOS\omni_gerador_artigos\venv\Lib\site-packages\flask\templating.py", line 65, in get_source
    return self._get_source_fast(environment, template)
           ^^^^^^^^^^^^^^^^^^^^^^^^^^^^^^^^^^^^^^^^^^^^
  File "C:\Users\SEDUC\Desktop\PROJETOS\omni_gerador_artigos\venv\Lib\site-packages\flask\templating.py", line 99, in _get_source_fast
    raise TemplateNotFound(template)
jinja2.exceptions.TemplateNotFound: index.html

During handling of the above exception, another exception occurred:

Traceback (most recent call last):
  File "C:\Users\SEDUC\Desktop\PROJETOS\omni_gerador_artigos\venv\Lib\site-packages\flask\app.py", line 1511, in wsgi_app
    response = self.full_dispatch_request()
               ^^^^^^^^^^^^^^^^^^^^^^^^^^^^
  File "C:\Users\SEDUC\Desktop\PROJETOS\omni_gerador_artigos\venv\Lib\site-packages\flask\app.py", line 919, in full_dispatch_request
    rv = self.handle_user_exception(e)
         ^^^^^^^^^^^^^^^^^^^^^^^^^^^^^
  File "C:\Users\SEDUC\Desktop\PROJETOS\omni_gerador_artigos\venv\Lib\site-packages\flask_cors\extension.py", line 176, in wrapped_function
    return cors_after_request(app.make_response(f(*args, **kwargs)))
                                                ^^^^^^^^^^^^^^^^^^
  File "C:\Users\SEDUC\Desktop\PROJETOS\omni_gerador_artigos\venv\Lib\site-packages\flask\app.py", line 917, in full_dispatch_request
    rv = self.dispatch_request()
         ^^^^^^^^^^^^^^^^^^^^^^^
  File "C:\Users\SEDUC\Desktop\PROJETOS\omni_gerador_artigos\venv\Lib\site-packages\flask\app.py", line 902, in dispatch_request
    return self.ensure_sync(self.view_functions[rule.endpoint])(**view_args)  # type: ignore[no-any-return]
           ^^^^^^^^^^^^^^^^^^^^^^^^^^^^^^^^^^^^^^^^^^^^^^^^^^^^^^^^^^^^^^^^^
  File "C:\Users\SEDUC\Desktop\PROJETOS\omni_gerador_artigos\venv\Lib\site-packages\flask_limiter\extension.py", line 1298, in __inner
    return cast(R, flask.current_app.ensure_sync(obj)(*a, **k))
                   ^^^^^^^^^^^^^^^^^^^^^^^^^^^^^^^^^^^^^^^^^^^
  File "D:\PROJETOS\SISTEMAS\omni_writer\app\routes.py", line 70, in wrapper
    resp = f(*args, **kwargs)
           ^^^^^^^^^^^^^^^^^^
  File "D:\PROJETOS\SISTEMAS\omni_writer\app\routes.py", line 193, in generate
    return render_template('index.html', modelos=MODELOS_SUPORTADOS)
           ^^^^^^^^^^^^^^^^^^^^^^^^^^^^^^^^^^^^^^^^^^^^^^^^^^^^^^^^^
  File "C:\Users\SEDUC\Desktop\PROJETOS\omni_gerador_artigos\venv\Lib\site-packages\flask\templating.py", line 149, in render_template
    template = app.jinja_env.get_or_select_template(template_name_or_list)
               ^^^^^^^^^^^^^^^^^^^^^^^^^^^^^^^^^^^^^^^^^^^^^^^^^^^^^^^^^^^
  File "C:\Users\SEDUC\Desktop\PROJETOS\omni_gerador_artigos\venv\Lib\site-packages\jinja2\environment.py", line 1087, in get_or_select_template
    return self.get_template(template_name_or_list, parent, globals)
           ^^^^^^^^^^^^^^^^^^^^^^^^^^^^^^^^^^^^^^^^^^^^^^^^^^^^^^^^^
  File "C:\Users\SEDUC\Desktop\PROJETOS\omni_gerador_artigos\venv\Lib\site-packages\jinja2\environment.py", line 1016, in get_template
    return self._load_template(name, globals)
           ^^^^^^^^^^^^^^^^^^^^^^^^^^^^^^^^^^
  File "C:\Users\SEDUC\Desktop\PROJETOS\omni_gerador_artigos\venv\Lib\site-packages\jinja2\environment.py", line 975, in _load_template
    template = self.loader.load(self, name, self.make_globals(globals))
               ^^^^^^^^^^^^^^^^^^^^^^^^^^^^^^^^^^^^^^^^^^^^^^^^^^^^^^^^
  File "C:\Users\SEDUC\Desktop\PROJETOS\omni_gerador_artigos\venv\Lib\site-packages\jinja2\loaders.py", line 126, in load
    source, filename, uptodate = self.get_source(environment, name)
                                 ^^^^^^^^^^^^^^^^^^^^^^^^^^^^^^^^^^
  File "C:\Users\SEDUC\Desktop\PROJETOS\omni_gerador_artigos\venv\Lib\site-packages\flask\templating.py", line 65, in get_source
    return self._get_source_fast(environment, template)
           ^^^^^^^^^^^^^^^^^^^^^^^^^^^^^^^^^^^^^^^^^^^^
  File "C:\Users\SEDUC\Desktop\PROJETOS\omni_gerador_artigos\venv\Lib\site-packages\flask\templating.py", line 99, in _get_source_fast
    raise TemplateNotFound(template)
jinja2.exceptions.TemplateNotFound: index.html
____________________ test_endpoint_protegido_token_valido _____________________

client = <FlaskClient <Flask 'app.app_factory'>>

    def test_endpoint_protegido_token_valido(client):
        # Simula token v├ílido
        headers = {"Authorization": "Bearer token_valido"}
        resp = client.get("/api/protegido", headers=headers)
>       assert resp.status_code == 200
E       assert 404 == 200
E        +  where 404 = <WrapperTestResponse streamed [404 NOT FOUND]>.status_code

tests\integration\test_autenticacao_permissao.py:15: AssertionError
=========================== short test summary info ===========================
FAILED tests\integration\test_api_template_generate.py::test_index_template
FAILED tests\integration\test_api_template_generate.py::test_generate_sem_dados
FAILED tests\integration\test_autenticacao_permissao.py::test_endpoint_protegido_token_valido
!!!!!!!!!!!!!!!!!!!!!!!!!! stopping after 3 failures !!!!!!!!!!!!!!!!!!!!!!!!!!
================== 3 failed, 2 passed, 18 warnings in 13.77s ==================
